/usr/lib/python3.4/importlib/_bootstrap.py:321: RemovedInDjango19Warning: django.utils.unittest will be removed in Django 1.9.
  return f(*args, **kwds)

..............F.FFE...
======================================================================
ERROR: test_player_api6 (tests.APItests3)
----------------------------------------------------------------------
Traceback (most recent call last):
  File "/home/david/cs373-idb/yafootballdb/tests.py", line 866, in test_player_api6
    response = urlopen(request)
  File "/usr/lib/python3.4/urllib/request.py", line 161, in urlopen
    return opener.open(url, data, timeout)
  File "/usr/lib/python3.4/urllib/request.py", line 469, in open
    response = meth(req, response)
  File "/usr/lib/python3.4/urllib/request.py", line 579, in http_response
    'http', request, response, code, msg, hdrs)
  File "/usr/lib/python3.4/urllib/request.py", line 501, in error
    result = self._call_chain(*args)
  File "/usr/lib/python3.4/urllib/request.py", line 441, in _call_chain
    result = func(*args)
  File "/usr/lib/python3.4/urllib/request.py", line 684, in http_error_302
    return self.parent.open(new, timeout=req.timeout)
  File "/usr/lib/python3.4/urllib/request.py", line 469, in open
    response = meth(req, response)
  File "/usr/lib/python3.4/urllib/request.py", line 579, in http_response
    'http', request, response, code, msg, hdrs)
  File "/usr/lib/python3.4/urllib/request.py", line 507, in error
    return self._call_chain(*args)
  File "/usr/lib/python3.4/urllib/request.py", line 441, in _call_chain
    result = func(*args)
  File "/usr/lib/python3.4/urllib/request.py", line 587, in http_error_default
    raise HTTPError(req.full_url, code, msg, hdrs, fp)
urllib.error.HTTPError: HTTP Error 404: NOT FOUND

======================================================================
FAIL: test_player_api2 (tests.APItests3)
----------------------------------------------------------------------
Traceback (most recent call last):
  File "/home/david/cs373-idb/yafootballdb/tests.py", line 802, in test_player_api2
    self.assertEqual(response_data["name"], "Bear Pascoe")
AssertionError: 'Brian Vogler' != 'Bear Pascoe'
- Brian Vogler
+ Bear Pascoe


======================================================================
FAIL: test_player_api4 (tests.APItests3)
----------------------------------------------------------------------
Traceback (most recent call last):
  File "/home/david/cs373-idb/yafootballdb/tests.py", line 836, in test_player_api4
    self.assertEqual(response_data["name"], "Ryan Fitzpatrick")
AssertionError: 'Geno Smith' != 'Ryan Fitzpatrick'
- Geno Smith
+ Ryan Fitzpatrick


======================================================================
FAIL: test_player_api5 (tests.APItests3)
----------------------------------------------------------------------
Traceback (most recent call last):
  File "/home/david/cs373-idb/yafootballdb/tests.py", line 853, in test_player_api5
    self.assertEqual(response_data["name"], "Dante Rosario")
AssertionError: 'Hroniss Grasu' != 'Dante Rosario'
- Hroniss Grasu
+ Dante Rosario


----------------------------------------------------------------------
Ran 22 tests in 2.517s

FAILED (failures=3, errors=1)
Creating test database for alias 'default'...
Destroying test database for alias 'default'...
